Traceback (most recent call last):
  File "/home/robert/anaconda3/lib/python3.9/site-packages/jupyter_cache/executors/utils.py", line 51, in single_nb_execution
    executenb(
  File "/home/robert/anaconda3/lib/python3.9/site-packages/nbclient/client.py", line 1204, in execute
    return NotebookClient(nb=nb, resources=resources, km=km, **kwargs).execute()
  File "/home/robert/anaconda3/lib/python3.9/site-packages/nbclient/util.py", line 84, in wrapped
    return just_run(coro(*args, **kwargs))
  File "/home/robert/anaconda3/lib/python3.9/site-packages/nbclient/util.py", line 62, in just_run
    return loop.run_until_complete(coro)
  File "/home/robert/anaconda3/lib/python3.9/asyncio/base_events.py", line 647, in run_until_complete
    return future.result()
  File "/home/robert/anaconda3/lib/python3.9/site-packages/nbclient/client.py", line 663, in async_execute
    await self.async_execute_cell(
  File "/home/robert/anaconda3/lib/python3.9/site-packages/nbclient/client.py", line 965, in async_execute_cell
    await self._check_raise_for_error(cell, cell_index, exec_reply)
  File "/home/robert/anaconda3/lib/python3.9/site-packages/nbclient/client.py", line 862, in _check_raise_for_error
    raise CellExecutionError.from_cell_and_msg(cell, exec_reply_content)
nbclient.exceptions.CellExecutionError: An error occurred while executing the following cell:
------------------
tauSinInf=tauSin.replace(tauSin.rhs.args[0],0)
display(tauSinInf)
------------------

[0;31m---------------------------------------------------------------------------[0m
[0;31mIndexError[0m                                Traceback (most recent call last)
Input [0;32mIn [26][0m, in [0;36m<cell line: 1>[0;34m()[0m
[0;32m----> 1[0m tauSinInf[38;5;241m=[39mtauSin[38;5;241m.[39mreplace([43mtauSin[49m[38;5;241;43m.[39;49m[43mrhs[49m[38;5;241;43m.[39;49m[43margs[49m[43m[[49m[38;5;241;43m0[39;49m[43m][49m,[38;5;241m0[39m)
[1;32m      2[0m display(tauSinInf)

[0;31mIndexError[0m: tuple index out of range
IndexError: tuple index out of range

